Exception in thread Thread-2 (run):
Traceback (most recent call last):
  File "/home/mila/o/ortizgas/env/cp310/lib/python3.10/threading.py", line 1009, in _bootstrap_inner
    self.run()
  File "/home/mila/o/ortizgas/env/cp310/lib/python3.10/threading.py", line 946, in run
    self._target(*self._args, **self._kwargs)
  File "/home/mila/o/ortizgas/CODE/milabench/benchmarks/recursiongfn/gflownet/src/gflownet/utils/multiprocessing_proxy.py", line 260, in run
