/network/scratch/o/ortizgas/data/milabench/venv/torch/lib/python3.10/site-packages/transformers/tokenization_utils_base.py:1601: FutureWarning: `clean_up_tokenization_spaces` was not set. It will be set to `True` by default. This behavior will be depracted in transformers v4.45, and will be then set to `False` by default. For more details check this issue: https://github.com/huggingface/transformers/issues/31884
  warnings.warn(
/network/scratch/o/ortizgas/data/milabench/venv/torch/lib/python3.10/site-packages/transformers/tokenization_utils_base.py:1601: FutureWarning: `clean_up_tokenization_spaces` was not set. It will be set to `True` by default. This behavior will be depracted in transformers v4.45, and will be then set to `False` by default. For more details check this issue: https://github.com/huggingface/transformers/issues/31884
  warnings.warn(
/network/scratch/o/ortizgas/data/milabench/venv/torch/lib/python3.10/site-packages/transformers/tokenization_utils_base.py:1601: FutureWarning: `clean_up_tokenization_spaces` was not set. It will be set to `True` by default. This behavior will be depracted in transformers v4.45, and will be then set to `False` by default. For more details check this issue: https://github.com/huggingface/transformers/issues/31884
  warnings.warn(
/network/scratch/o/ortizgas/data/milabench/venv/torch/lib/python3.10/site-packages/transformers/tokenization_utils_base.py:1601: FutureWarning: `clean_up_tokenization_spaces` was not set. It will be set to `True` by default. This behavior will be depracted in transformers v4.45, and will be then set to `False` by default. For more details check this issue: https://github.com/huggingface/transformers/issues/31884
  warnings.warn(
Some weights of GPTNeoXForSequenceClassification were not initialized from the model checkpoint at EleutherAI/pythia-160m and are newly initialized: ['score.weight']
You should probably TRAIN this model on a down-stream task to be able to use it for predictions and inference.
Some weights of GPTNeoXForSequenceClassification were not initialized from the model checkpoint at EleutherAI/pythia-160m and are newly initialized: ['score.weight']
You should probably TRAIN this model on a down-stream task to be able to use it for predictions and inference.
Some weights of GPTNeoXForSequenceClassification were not initialized from the model checkpoint at EleutherAI/pythia-160m and are newly initialized: ['score.weight']
You should probably TRAIN this model on a down-stream task to be able to use it for predictions and inference.
Some weights of GPTNeoXForSequenceClassification were not initialized from the model checkpoint at EleutherAI/pythia-160m and are newly initialized: ['score.weight']
You should probably TRAIN this model on a down-stream task to be able to use it for predictions and inference.
Some weights of GPTNeoXForSequenceClassification were not initialized from the model checkpoint at EleutherAI/pythia-160m and are newly initialized: ['score.weight']
You should probably TRAIN this model on a down-stream task to be able to use it for predictions and inference.
Some weights of GPTNeoXForSequenceClassification were not initialized from the model checkpoint at EleutherAI/pythia-160m and are newly initialized: ['score.weight']
You should probably TRAIN this model on a down-stream task to be able to use it for predictions and inference.
Some weights of GPTNeoXForSequenceClassification were not initialized from the model checkpoint at EleutherAI/pythia-160m and are newly initialized: ['score.weight']
You should probably TRAIN this model on a down-stream task to be able to use it for predictions and inference.
Some weights of GPTNeoXForSequenceClassification were not initialized from the model checkpoint at EleutherAI/pythia-160m and are newly initialized: ['score.weight']
You should probably TRAIN this model on a down-stream task to be able to use it for predictions and inference.
Using the latest cached version of the dataset since trl-internal-testing/descriptiveness-sentiment-trl-style couldn't be found on the Hugging Face Hub
Found the latest cached dataset configuration 'default' at /network/scratch/o/ortizgas/data/milabench/cache/huggingface/datasets/trl-internal-testing___descriptiveness-sentiment-trl-style/default/0.0.0/71d6badc4b89e0316cce4a01e6db3f3e7195dc84 (last modified on Tue Nov  5 06:26:38 2024).
  0%|          | 0/23 [00:00<?, ?it/s]                                        0%|          | 0/23 [00:32<?, ?it/s]  4%|▍         | 1/23 [00:32<11:45, 32.07s/it]                                                4%|▍         | 1/23 [00:56<11:45, 32.07s/it]  9%|▊         | 2/23 [00:56<09:44, 27.83s/it]                                                9%|▊         | 2/23 [01:22<09:44, 27.83s/it] 13%|█▎        | 3/23 [01:22<08:53, 26.66s/it]                                               13%|█▎        | 3/23 [01:47<08:53, 26.66s/it] 17%|█▋        | 4/23 [01:47<08:19, 26.27s/it][rank3]: Traceback (most recent call last):
[rank3]:   File "/home/mila/o/ortizgas/CODE/milabench/benchmarks/rlhf/main.py", line 133, in <module>
[rank3]:     main()
[rank3]:   File "/home/mila/o/ortizgas/CODE/milabench/benchmarks/rlhf/main.py", line 124, in main
[rank3]:     trainer.train()
[rank3]:   File "/network/scratch/o/ortizgas/data/milabench/venv/torch/lib/python3.10/site-packages/trl/trainer/ppov2_trainer.py", line 465, in train
[rank3]:     accelerator.backward(loss)
[rank3]:   File "/network/scratch/o/ortizgas/data/milabench/venv/torch/lib/python3.10/site-packages/accelerate/accelerator.py", line 2196, in backward
[rank3]:     loss.backward(**kwargs)
[rank3]:   File "/network/scratch/o/ortizgas/data/milabench/venv/torch/lib/python3.10/site-packages/torch/_tensor.py", line 521, in backward
[rank3]:     torch.autograd.backward(
[rank3]:   File "/network/scratch/o/ortizgas/data/milabench/venv/torch/lib/python3.10/site-packages/torch/autograd/__init__.py", line 289, in backward
[rank3]:     _engine_run_backward(
[rank3]:   File "/network/scratch/o/ortizgas/data/milabench/venv/torch/lib/python3.10/site-packages/torch/autograd/graph.py", line 768, in _engine_run_backward
[rank3]:     return Variable._execution_engine.run_backward(  # Calls into the C++ engine to run the backward pass
[rank3]: torch.OutOfMemoryError: CUDA out of memory. Tried to allocate 1.79 GiB. GPU 3 has a total capacity of 44.47 GiB of which 1.46 GiB is free. Including non-PyTorch memory, this process has 43.01 GiB memory in use. Of the allocated memory 39.04 GiB is allocated by PyTorch, and 3.66 GiB is reserved by PyTorch but unallocated. If reserved but unallocated memory is large try setting PYTORCH_CUDA_ALLOC_CONF=expandable_segments:True to avoid fragmentation.  See documentation for Memory Management  (https://pytorch.org/docs/stable/notes/cuda.html#environment-variables)
W1212 15:10:43.525727 139723686028416 torch/distributed/elastic/agent/server/api.py:688] Received Signals.SIGTERM death signal, shutting down workers
W1212 15:10:43.526152 139723686028416 torch/distributed/elastic/multiprocessing/api.py:858] Sending process 1225299 closing signal SIGTERM
W1212 15:10:43.526758 139723686028416 torch/distributed/elastic/multiprocessing/api.py:858] Sending process 1225300 closing signal SIGTERM
W1212 15:10:43.527587 139723686028416 torch/distributed/elastic/multiprocessing/api.py:858] Sending process 1225301 closing signal SIGTERM
W1212 15:10:43.527908 139723686028416 torch/distributed/elastic/multiprocessing/api.py:858] Sending process 1225302 closing signal SIGTERM
Traceback (most recent call last):
  File "/network/scratch/o/ortizgas/data/milabench/venv/torch/bin/accelerate", line 8, in <module>
    sys.exit(main())
  File "/network/scratch/o/ortizgas/data/milabench/venv/torch/lib/python3.10/site-packages/accelerate/commands/accelerate_cli.py", line 48, in main
    args.func(args)
  File "/network/scratch/o/ortizgas/data/milabench/venv/torch/lib/python3.10/site-packages/accelerate/commands/launch.py", line 1165, in launch_command
    multi_gpu_launcher(args)
  File "/network/scratch/o/ortizgas/data/milabench/venv/torch/lib/python3.10/site-packages/accelerate/commands/launch.py", line 799, in multi_gpu_launcher
    distrib_run.run(args)
  File "/network/scratch/o/ortizgas/data/milabench/venv/torch/lib/python3.10/site-packages/torch/distributed/run.py", line 892, in run
    elastic_launch(
  File "/network/scratch/o/ortizgas/data/milabench/venv/torch/lib/python3.10/site-packages/torch/distributed/launcher/api.py", line 133, in __call__
    return launch_agent(self._config, self._entrypoint, list(args))
  File "/network/scratch/o/ortizgas/data/milabench/venv/torch/lib/python3.10/site-packages/torch/distributed/launcher/api.py", line 255, in launch_agent
    result = agent.run()
  File "/network/scratch/o/ortizgas/data/milabench/venv/torch/lib/python3.10/site-packages/torch/distributed/elastic/metrics/api.py", line 124, in wrapper
    result = f(*args, **kwargs)
  File "/network/scratch/o/ortizgas/data/milabench/venv/torch/lib/python3.10/site-packages/torch/distributed/elastic/agent/server/api.py", line 680, in run
    result = self._invoke_run(role)
  File "/network/scratch/o/ortizgas/data/milabench/venv/torch/lib/python3.10/site-packages/torch/distributed/elastic/agent/server/api.py", line 835, in _invoke_run
    time.sleep(monitor_interval)
  File "/network/scratch/o/ortizgas/data/milabench/venv/torch/lib/python3.10/site-packages/torch/distributed/elastic/multiprocessing/api.py", line 79, in _terminate_process_handler
    raise SignalException(f"Process {os.getpid()} got signal: {sigval}", sigval=sigval)
torch.distributed.elastic.multiprocessing.api.SignalException: Process 1225215 got signal: 15
