/network/scratch/o/ortizgas/data/milabench/venv/torch/lib/python3.10/site-packages/transformers/tokenization_utils_base.py:1601: FutureWarning: `clean_up_tokenization_spaces` was not set. It will be set to `True` by default. This behavior will be depracted in transformers v4.45, and will be then set to `False` by default. For more details check this issue: https://github.com/huggingface/transformers/issues/31884
  warnings.warn(
/network/scratch/o/ortizgas/data/milabench/venv/torch/lib/python3.10/site-packages/transformers/tokenization_utils_base.py:1601: FutureWarning: `clean_up_tokenization_spaces` was not set. It will be set to `True` by default. This behavior will be depracted in transformers v4.45, and will be then set to `False` by default. For more details check this issue: https://github.com/huggingface/transformers/issues/31884
  warnings.warn(
/network/scratch/o/ortizgas/data/milabench/venv/torch/lib/python3.10/site-packages/transformers/tokenization_utils_base.py:1601: FutureWarning: `clean_up_tokenization_spaces` was not set. It will be set to `True` by default. This behavior will be depracted in transformers v4.45, and will be then set to `False` by default. For more details check this issue: https://github.com/huggingface/transformers/issues/31884
  warnings.warn(
/network/scratch/o/ortizgas/data/milabench/venv/torch/lib/python3.10/site-packages/transformers/tokenization_utils_base.py:1601: FutureWarning: `clean_up_tokenization_spaces` was not set. It will be set to `True` by default. This behavior will be depracted in transformers v4.45, and will be then set to `False` by default. For more details check this issue: https://github.com/huggingface/transformers/issues/31884
  warnings.warn(
Some weights of GPTNeoXForSequenceClassification were not initialized from the model checkpoint at EleutherAI/pythia-160m and are newly initialized: ['score.weight']
You should probably TRAIN this model on a down-stream task to be able to use it for predictions and inference.
Some weights of GPTNeoXForSequenceClassification were not initialized from the model checkpoint at EleutherAI/pythia-160m and are newly initialized: ['score.weight']
You should probably TRAIN this model on a down-stream task to be able to use it for predictions and inference.
Some weights of GPTNeoXForSequenceClassification were not initialized from the model checkpoint at EleutherAI/pythia-160m and are newly initialized: ['score.weight']
You should probably TRAIN this model on a down-stream task to be able to use it for predictions and inference.
Some weights of GPTNeoXForSequenceClassification were not initialized from the model checkpoint at EleutherAI/pythia-160m and are newly initialized: ['score.weight']
You should probably TRAIN this model on a down-stream task to be able to use it for predictions and inference.
Some weights of GPTNeoXForSequenceClassification were not initialized from the model checkpoint at EleutherAI/pythia-160m and are newly initialized: ['score.weight']
You should probably TRAIN this model on a down-stream task to be able to use it for predictions and inference.
Some weights of GPTNeoXForSequenceClassification were not initialized from the model checkpoint at EleutherAI/pythia-160m and are newly initialized: ['score.weight']
You should probably TRAIN this model on a down-stream task to be able to use it for predictions and inference.
Some weights of GPTNeoXForSequenceClassification were not initialized from the model checkpoint at EleutherAI/pythia-160m and are newly initialized: ['score.weight']
You should probably TRAIN this model on a down-stream task to be able to use it for predictions and inference.
Some weights of GPTNeoXForSequenceClassification were not initialized from the model checkpoint at EleutherAI/pythia-160m and are newly initialized: ['score.weight']
You should probably TRAIN this model on a down-stream task to be able to use it for predictions and inference.
  0%|          | 0/22 [00:00<?, ?it/s]                                        0%|          | 0/22 [00:12<?, ?it/s]  5%|▍         | 1/22 [00:12<04:24, 12.57s/it]                                                5%|▍         | 1/22 [00:19<04:24, 12.57s/it]  9%|▉         | 2/22 [00:19<03:02,  9.13s/it]                                                9%|▉         | 2/22 [00:26<03:02,  9.13s/it] 14%|█▎        | 3/22 [00:26<02:32,  8.04s/it]                                               14%|█▎        | 3/22 [00:32<02:32,  8.04s/it] 18%|█▊        | 4/22 [00:32<02:15,  7.51s/it]                                               18%|█▊        | 4/22 [00:39<02:15,  7.51s/it] 23%|██▎       | 5/22 [00:39<02:04,  7.31s/it][rank1]: Traceback (most recent call last):
[rank1]:   File "/home/mila/o/ortizgas/CODE/milabench/benchmarks/rlhf/main.py", line 133, in <module>
[rank1]:     main()
[rank1]:   File "/home/mila/o/ortizgas/CODE/milabench/benchmarks/rlhf/main.py", line 124, in main
[rank1]:     trainer.train()
[rank1]:   File "/network/scratch/o/ortizgas/data/milabench/venv/torch/lib/python3.10/site-packages/trl/trainer/ppov2_trainer.py", line 465, in train
[rank1]:     accelerator.backward(loss)
[rank1]:   File "/network/scratch/o/ortizgas/data/milabench/venv/torch/lib/python3.10/site-packages/accelerate/accelerator.py", line 2196, in backward
[rank1]:     loss.backward(**kwargs)
[rank1]:   File "/network/scratch/o/ortizgas/data/milabench/venv/torch/lib/python3.10/site-packages/torch/_tensor.py", line 521, in backward
[rank1]:     torch.autograd.backward(
[rank1]:   File "/network/scratch/o/ortizgas/data/milabench/venv/torch/lib/python3.10/site-packages/torch/autograd/__init__.py", line 289, in backward
[rank1]:     _engine_run_backward(
[rank1]:   File "/network/scratch/o/ortizgas/data/milabench/venv/torch/lib/python3.10/site-packages/torch/autograd/graph.py", line 768, in _engine_run_backward
[rank1]:     return Variable._execution_engine.run_backward(  # Calls into the C++ engine to run the backward pass
[rank1]: torch.OutOfMemoryError: CUDA out of memory. Tried to allocate 1.91 GiB. GPU 1 has a total capacity of 44.64 GiB of which 1.72 GiB is free. Including non-PyTorch memory, this process has 42.91 GiB memory in use. Of the allocated memory 41.77 GiB is allocated by PyTorch, and 495.94 MiB is reserved by PyTorch but unallocated. If reserved but unallocated memory is large try setting PYTORCH_CUDA_ALLOC_CONF=expandable_segments:True to avoid fragmentation.  See documentation for Memory Management  (https://pytorch.org/docs/stable/notes/cuda.html#environment-variables)
W1211 05:17:58.174637 140544925476672 torch/distributed/elastic/multiprocessing/api.py:858] Sending process 3670707 closing signal SIGTERM
W1211 05:17:58.175150 140544925476672 torch/distributed/elastic/multiprocessing/api.py:858] Sending process 3670709 closing signal SIGTERM
W1211 05:17:58.175474 140544925476672 torch/distributed/elastic/multiprocessing/api.py:858] Sending process 3670710 closing signal SIGTERM
E1211 05:17:58.603344 140544925476672 torch/distributed/elastic/multiprocessing/api.py:833] failed (exitcode: 1) local_rank: 1 (pid: 3670708) of binary: /network/scratch/o/ortizgas/data/milabench/venv/torch/bin/python
Traceback (most recent call last):
  File "/network/scratch/o/ortizgas/data/milabench/venv/torch/bin/accelerate", line 8, in <module>
    sys.exit(main())
  File "/network/scratch/o/ortizgas/data/milabench/venv/torch/lib/python3.10/site-packages/accelerate/commands/accelerate_cli.py", line 48, in main
    args.func(args)
  File "/network/scratch/o/ortizgas/data/milabench/venv/torch/lib/python3.10/site-packages/accelerate/commands/launch.py", line 1165, in launch_command
    multi_gpu_launcher(args)
  File "/network/scratch/o/ortizgas/data/milabench/venv/torch/lib/python3.10/site-packages/accelerate/commands/launch.py", line 799, in multi_gpu_launcher
    distrib_run.run(args)
  File "/network/scratch/o/ortizgas/data/milabench/venv/torch/lib/python3.10/site-packages/torch/distributed/run.py", line 892, in run
    elastic_launch(
  File "/network/scratch/o/ortizgas/data/milabench/venv/torch/lib/python3.10/site-packages/torch/distributed/launcher/api.py", line 133, in __call__
    return launch_agent(self._config, self._entrypoint, list(args))
  File "/network/scratch/o/ortizgas/data/milabench/venv/torch/lib/python3.10/site-packages/torch/distributed/launcher/api.py", line 264, in launch_agent
    raise ChildFailedError(
torch.distributed.elastic.multiprocessing.errors.ChildFailedError: 
============================================================
/home/mila/o/ortizgas/CODE/milabench/benchmarks/rlhf/main.py FAILED
------------------------------------------------------------
Failures:
  <NO_OTHER_FAILURES>
------------------------------------------------------------
Root Cause (first observed failure):
[0]:
  time      : 2024-12-11_05:17:58
  host      : cn-l040.server.mila.quebec
  rank      : 1 (local_rank: 1)
  exitcode  : 1 (pid: 3670708)
  error_file: <N/A>
  traceback : To enable traceback see: https://pytorch.org/docs/stable/elastic/errors.html
============================================================
