/network/scratch/o/ortizgas/data/milabench/venv/torch/lib/python3.10/site-packages/transformers/tokenization_utils_base.py:1601: FutureWarning: `clean_up_tokenization_spaces` was not set. It will be set to `True` by default. This behavior will be depracted in transformers v4.45, and will be then set to `False` by default. For more details check this issue: https://github.com/huggingface/transformers/issues/31884
  warnings.warn(
/network/scratch/o/ortizgas/data/milabench/venv/torch/lib/python3.10/site-packages/transformers/tokenization_utils_base.py:1601: FutureWarning: `clean_up_tokenization_spaces` was not set. It will be set to `True` by default. This behavior will be depracted in transformers v4.45, and will be then set to `False` by default. For more details check this issue: https://github.com/huggingface/transformers/issues/31884
  warnings.warn(
/network/scratch/o/ortizgas/data/milabench/venv/torch/lib/python3.10/site-packages/transformers/tokenization_utils_base.py:1601: FutureWarning: `clean_up_tokenization_spaces` was not set. It will be set to `True` by default. This behavior will be depracted in transformers v4.45, and will be then set to `False` by default. For more details check this issue: https://github.com/huggingface/transformers/issues/31884
  warnings.warn(
/network/scratch/o/ortizgas/data/milabench/venv/torch/lib/python3.10/site-packages/transformers/tokenization_utils_base.py:1601: FutureWarning: `clean_up_tokenization_spaces` was not set. It will be set to `True` by default. This behavior will be depracted in transformers v4.45, and will be then set to `False` by default. For more details check this issue: https://github.com/huggingface/transformers/issues/31884
  warnings.warn(
Some weights of GPTNeoXForSequenceClassification were not initialized from the model checkpoint at EleutherAI/pythia-160m and are newly initialized: ['score.weight']
You should probably TRAIN this model on a down-stream task to be able to use it for predictions and inference.
Some weights of GPTNeoXForSequenceClassification were not initialized from the model checkpoint at EleutherAI/pythia-160m and are newly initialized: ['score.weight']
You should probably TRAIN this model on a down-stream task to be able to use it for predictions and inference.
Some weights of GPTNeoXForSequenceClassification were not initialized from the model checkpoint at EleutherAI/pythia-160m and are newly initialized: ['score.weight']
You should probably TRAIN this model on a down-stream task to be able to use it for predictions and inference.
Some weights of GPTNeoXForSequenceClassification were not initialized from the model checkpoint at EleutherAI/pythia-160m and are newly initialized: ['score.weight']
You should probably TRAIN this model on a down-stream task to be able to use it for predictions and inference.
Some weights of GPTNeoXForSequenceClassification were not initialized from the model checkpoint at EleutherAI/pythia-160m and are newly initialized: ['score.weight']
You should probably TRAIN this model on a down-stream task to be able to use it for predictions and inference.
Some weights of GPTNeoXForSequenceClassification were not initialized from the model checkpoint at EleutherAI/pythia-160m and are newly initialized: ['score.weight']
You should probably TRAIN this model on a down-stream task to be able to use it for predictions and inference.
Some weights of GPTNeoXForSequenceClassification were not initialized from the model checkpoint at EleutherAI/pythia-160m and are newly initialized: ['score.weight']
You should probably TRAIN this model on a down-stream task to be able to use it for predictions and inference.
Some weights of GPTNeoXForSequenceClassification were not initialized from the model checkpoint at EleutherAI/pythia-160m and are newly initialized: ['score.weight']
You should probably TRAIN this model on a down-stream task to be able to use it for predictions and inference.
  0%|          | 0/34 [00:00<?, ?it/s][rank0]: Traceback (most recent call last):
[rank0]:   File "/home/mila/o/ortizgas/CODE/milabench/benchmarks/rlhf/main.py", line 133, in <module>
[rank0]:     main()
[rank0]:   File "/home/mila/o/ortizgas/CODE/milabench/benchmarks/rlhf/main.py", line 124, in main
[rank0]:     trainer.train()
[rank0]:   File "/network/scratch/o/ortizgas/data/milabench/venv/torch/lib/python3.10/site-packages/trl/trainer/ppov2_trainer.py", line 465, in train
[rank0]:     accelerator.backward(loss)
[rank0]:   File "/network/scratch/o/ortizgas/data/milabench/venv/torch/lib/python3.10/site-packages/accelerate/accelerator.py", line 2196, in backward
[rank0]:     loss.backward(**kwargs)
[rank0]:   File "/network/scratch/o/ortizgas/data/milabench/venv/torch/lib/python3.10/site-packages/torch/_tensor.py", line 521, in backward
[rank0]:     torch.autograd.backward(
[rank0]:   File "/network/scratch/o/ortizgas/data/milabench/venv/torch/lib/python3.10/site-packages/torch/autograd/__init__.py", line 289, in backward
[rank0]:     _engine_run_backward(
[rank0]:   File "/network/scratch/o/ortizgas/data/milabench/venv/torch/lib/python3.10/site-packages/torch/autograd/graph.py", line 768, in _engine_run_backward
[rank0]:     return Variable._execution_engine.run_backward(  # Calls into the C++ engine to run the backward pass
[rank0]: torch.OutOfMemoryError: CUDA out of memory. Tried to allocate 1.19 GiB. GPU 0 has a total capacity of 31.74 GiB of which 1.06 GiB is free. Process 2039027 has 306.00 MiB memory in use. Process 2039029 has 306.00 MiB memory in use. Process 2039028 has 306.00 MiB memory in use. Including non-PyTorch memory, this process has 29.78 GiB memory in use. Of the allocated memory 27.74 GiB is allocated by PyTorch, and 1.54 GiB is reserved by PyTorch but unallocated. If reserved but unallocated memory is large try setting PYTORCH_CUDA_ALLOC_CONF=expandable_segments:True to avoid fragmentation.  See documentation for Memory Management  (https://pytorch.org/docs/stable/notes/cuda.html#environment-variables)
[rank1]: Traceback (most recent call last):
[rank1]:   File "/home/mila/o/ortizgas/CODE/milabench/benchmarks/rlhf/main.py", line 133, in <module>
[rank1]:     main()
[rank1]:   File "/home/mila/o/ortizgas/CODE/milabench/benchmarks/rlhf/main.py", line 124, in main
[rank1]:     trainer.train()
[rank1]:   File "/network/scratch/o/ortizgas/data/milabench/venv/torch/lib/python3.10/site-packages/trl/trainer/ppov2_trainer.py", line 465, in train
[rank1]:     accelerator.backward(loss)
[rank1]:   File "/network/scratch/o/ortizgas/data/milabench/venv/torch/lib/python3.10/site-packages/accelerate/accelerator.py", line 2196, in backward
[rank1]:     loss.backward(**kwargs)
[rank1]:   File "/network/scratch/o/ortizgas/data/milabench/venv/torch/lib/python3.10/site-packages/torch/_tensor.py", line 521, in backward
[rank1]:     torch.autograd.backward(
[rank1]:   File "/network/scratch/o/ortizgas/data/milabench/venv/torch/lib/python3.10/site-packages/torch/autograd/__init__.py", line 289, in backward
[rank1]:     _engine_run_backward(
[rank1]:   File "/network/scratch/o/ortizgas/data/milabench/venv/torch/lib/python3.10/site-packages/torch/autograd/graph.py", line 768, in _engine_run_backward
[rank1]:     return Variable._execution_engine.run_backward(  # Calls into the C++ engine to run the backward pass
[rank1]: torch.OutOfMemoryError: CUDA out of memory. Tried to allocate 1.19 GiB. GPU 1 has a total capacity of 31.74 GiB of which 885.38 MiB is free. Including non-PyTorch memory, this process has 30.87 GiB memory in use. Of the allocated memory 27.53 GiB is allocated by PyTorch, and 2.75 GiB is reserved by PyTorch but unallocated. If reserved but unallocated memory is large try setting PYTORCH_CUDA_ALLOC_CONF=expandable_segments:True to avoid fragmentation.  See documentation for Memory Management  (https://pytorch.org/docs/stable/notes/cuda.html#environment-variables)
[rank2]: Traceback (most recent call last):
[rank2]:   File "/home/mila/o/ortizgas/CODE/milabench/benchmarks/rlhf/main.py", line 133, in <module>
[rank2]:     main()
[rank2]:   File "/home/mila/o/ortizgas/CODE/milabench/benchmarks/rlhf/main.py", line 124, in main
[rank2]:     trainer.train()
[rank2]:   File "/network/scratch/o/ortizgas/data/milabench/venv/torch/lib/python3.10/site-packages/trl/trainer/ppov2_trainer.py", line 465, in train
[rank2]:     accelerator.backward(loss)
[rank2]:   File "/network/scratch/o/ortizgas/data/milabench/venv/torch/lib/python3.10/site-packages/accelerate/accelerator.py", line 2196, in backward
[rank2]:     loss.backward(**kwargs)
[rank2]:   File "/network/scratch/o/ortizgas/data/milabench/venv/torch/lib/python3.10/site-packages/torch/_tensor.py", line 521, in backward
[rank2]:     torch.autograd.backward(
[rank2]:   File "/network/scratch/o/ortizgas/data/milabench/venv/torch/lib/python3.10/site-packages/torch/autograd/__init__.py", line 289, in backward
[rank2]:     _engine_run_backward(
[rank2]:   File "/network/scratch/o/ortizgas/data/milabench/venv/torch/lib/python3.10/site-packages/torch/autograd/graph.py", line 768, in _engine_run_backward
[rank2]:     return Variable._execution_engine.run_backward(  # Calls into the C++ engine to run the backward pass
[rank2]: torch.OutOfMemoryError: CUDA out of memory. Tried to allocate 1.19 GiB. GPU 2 has a total capacity of 31.74 GiB of which 885.38 MiB is free. Including non-PyTorch memory, this process has 30.87 GiB memory in use. Of the allocated memory 27.53 GiB is allocated by PyTorch, and 2.75 GiB is reserved by PyTorch but unallocated. If reserved but unallocated memory is large try setting PYTORCH_CUDA_ALLOC_CONF=expandable_segments:True to avoid fragmentation.  See documentation for Memory Management  (https://pytorch.org/docs/stable/notes/cuda.html#environment-variables)
  0%|          | 0/34 [00:15<?, ?it/s]
[rank0]:[W1213 05:56:02.324182951 ProcessGroupNCCL.cpp:1168] Warning: WARNING: process group has NOT been destroyed before we destruct ProcessGroupNCCL. On normal program exit, the application should call destroy_process_group to ensure that any pending NCCL operations have finished in this process. In rare cases this process can exit before this point and block the progress of another member of the process group. This constraint has always been present,  but this warning has only been added since PyTorch 2.4 (function operator())
W1213 05:56:15.295338 139865920660608 torch/distributed/elastic/multiprocessing/api.py:858] Sending process 2039026 closing signal SIGTERM
W1213 05:56:15.295614 139865920660608 torch/distributed/elastic/multiprocessing/api.py:858] Sending process 2039028 closing signal SIGTERM
W1213 05:56:15.295921 139865920660608 torch/distributed/elastic/multiprocessing/api.py:858] Sending process 2039029 closing signal SIGTERM
E1213 05:56:16.076893 139865920660608 torch/distributed/elastic/multiprocessing/api.py:833] failed (exitcode: 1) local_rank: 1 (pid: 2039027) of binary: /network/scratch/o/ortizgas/data/milabench/venv/torch/bin/python
Traceback (most recent call last):
  File "/network/scratch/o/ortizgas/data/milabench/venv/torch/bin/accelerate", line 8, in <module>
    sys.exit(main())
  File "/network/scratch/o/ortizgas/data/milabench/venv/torch/lib/python3.10/site-packages/accelerate/commands/accelerate_cli.py", line 48, in main
    args.func(args)
  File "/network/scratch/o/ortizgas/data/milabench/venv/torch/lib/python3.10/site-packages/accelerate/commands/launch.py", line 1165, in launch_command
    multi_gpu_launcher(args)
  File "/network/scratch/o/ortizgas/data/milabench/venv/torch/lib/python3.10/site-packages/accelerate/commands/launch.py", line 799, in multi_gpu_launcher
    distrib_run.run(args)
  File "/network/scratch/o/ortizgas/data/milabench/venv/torch/lib/python3.10/site-packages/torch/distributed/run.py", line 892, in run
    elastic_launch(
  File "/network/scratch/o/ortizgas/data/milabench/venv/torch/lib/python3.10/site-packages/torch/distributed/launcher/api.py", line 133, in __call__
    return launch_agent(self._config, self._entrypoint, list(args))
  File "/network/scratch/o/ortizgas/data/milabench/venv/torch/lib/python3.10/site-packages/torch/distributed/launcher/api.py", line 264, in launch_agent
    raise ChildFailedError(
torch.distributed.elastic.multiprocessing.errors.ChildFailedError: 
============================================================
/home/mila/o/ortizgas/CODE/milabench/benchmarks/rlhf/main.py FAILED
------------------------------------------------------------
Failures:
  <NO_OTHER_FAILURES>
------------------------------------------------------------
Root Cause (first observed failure):
[0]:
  time      : 2024-12-13_05:56:15
  host      : cn-e002.server.mila.quebec
  rank      : 1 (local_rank: 1)
  exitcode  : 1 (pid: 2039027)
  error_file: <N/A>
  traceback : To enable traceback see: https://pytorch.org/docs/stable/elastic/errors.html
============================================================
