Exception in thread Thread-2 (run):
Traceback (most recent call last):
  File "/home/mila/o/ortizgas/env/cp310/lib/python3.10/threading.py", line 1009, in _bootstrap_inner
    self.run()
  File "/home/mila/o/ortizgas/env/cp310/lib/python3.10/threading.py", line 946, in run
    self._target(*self._args, **self._kwargs)
  File "/home/mila/o/ortizgas/CODE/milabench/benchmarks/recursiongfn/gflownet/src/gflownet/utils/multiprocessing_proxy.py", line 260, in run
    r = self.decode(q.get(True, 1e-5))
  File "/home/mila/o/ortizgas/env/cp310/lib/python3.10/multiprocessing/queues.py", line 117, in get
    res = self._recv_bytes()
  File "/home/mila/o/ortizgas/env/cp310/lib/python3.10/multiprocessing/connection.py", line 221, in recv_bytes
    buf = self._recv_bytes(maxlength)
  File "/home/mila/o/ortizgas/env/cp310/lib/python3.10/multiprocessing/connection.py", line 419, in _recv_bytes
