/network/scratch/o/ortizgas/data/milabench/venv/torch/lib/python3.10/site-packages/transformers/tokenization_utils_base.py:1601: FutureWarning: `clean_up_tokenization_spaces` was not set. It will be set to `True` by default. This behavior will be depracted in transformers v4.45, and will be then set to `False` by default. For more details check this issue: https://github.com/huggingface/transformers/issues/31884
  warnings.warn(
/network/scratch/o/ortizgas/data/milabench/venv/torch/lib/python3.10/site-packages/transformers/tokenization_utils_base.py:1601: FutureWarning: `clean_up_tokenization_spaces` was not set. It will be set to `True` by default. This behavior will be depracted in transformers v4.45, and will be then set to `False` by default. For more details check this issue: https://github.com/huggingface/transformers/issues/31884
  warnings.warn(
/network/scratch/o/ortizgas/data/milabench/venv/torch/lib/python3.10/site-packages/transformers/tokenization_utils_base.py:1601: FutureWarning: `clean_up_tokenization_spaces` was not set. It will be set to `True` by default. This behavior will be depracted in transformers v4.45, and will be then set to `False` by default. For more details check this issue: https://github.com/huggingface/transformers/issues/31884
  warnings.warn(
/network/scratch/o/ortizgas/data/milabench/venv/torch/lib/python3.10/site-packages/transformers/tokenization_utils_base.py:1601: FutureWarning: `clean_up_tokenization_spaces` was not set. It will be set to `True` by default. This behavior will be depracted in transformers v4.45, and will be then set to `False` by default. For more details check this issue: https://github.com/huggingface/transformers/issues/31884
  warnings.warn(
Some weights of GPTNeoXForSequenceClassification were not initialized from the model checkpoint at EleutherAI/pythia-160m and are newly initialized: ['score.weight']
You should probably TRAIN this model on a down-stream task to be able to use it for predictions and inference.
Some weights of GPTNeoXForSequenceClassification were not initialized from the model checkpoint at EleutherAI/pythia-160m and are newly initialized: ['score.weight']
You should probably TRAIN this model on a down-stream task to be able to use it for predictions and inference.
Some weights of GPTNeoXForSequenceClassification were not initialized from the model checkpoint at EleutherAI/pythia-160m and are newly initialized: ['score.weight']
You should probably TRAIN this model on a down-stream task to be able to use it for predictions and inference.
Some weights of GPTNeoXForSequenceClassification were not initialized from the model checkpoint at EleutherAI/pythia-160m and are newly initialized: ['score.weight']
You should probably TRAIN this model on a down-stream task to be able to use it for predictions and inference.
Some weights of GPTNeoXForSequenceClassification were not initialized from the model checkpoint at EleutherAI/pythia-160m and are newly initialized: ['score.weight']
You should probably TRAIN this model on a down-stream task to be able to use it for predictions and inference.
Some weights of GPTNeoXForSequenceClassification were not initialized from the model checkpoint at EleutherAI/pythia-160m and are newly initialized: ['score.weight']
You should probably TRAIN this model on a down-stream task to be able to use it for predictions and inference.
Some weights of GPTNeoXForSequenceClassification were not initialized from the model checkpoint at EleutherAI/pythia-160m and are newly initialized: ['score.weight']
You should probably TRAIN this model on a down-stream task to be able to use it for predictions and inference.
Some weights of GPTNeoXForSequenceClassification were not initialized from the model checkpoint at EleutherAI/pythia-160m and are newly initialized: ['score.weight']
You should probably TRAIN this model on a down-stream task to be able to use it for predictions and inference.
  0%|          | 0/8 [00:00<?, ?it/s][rank0]: Traceback (most recent call last):
[rank0]:   File "/home/mila/o/ortizgas/CODE/milabench/benchmarks/rlhf/main.py", line 133, in <module>
[rank0]:     main()
[rank0]:   File "/home/mila/o/ortizgas/CODE/milabench/benchmarks/rlhf/main.py", line 124, in main
[rank0]:     trainer.train()
[rank0]:   File "/network/scratch/o/ortizgas/data/milabench/venv/torch/lib/python3.10/site-packages/trl/trainer/ppov2_trainer.py", line 465, in train
[rank0]:     accelerator.backward(loss)
[rank0]:   File "/network/scratch/o/ortizgas/data/milabench/venv/torch/lib/python3.10/site-packages/accelerate/accelerator.py", line 2196, in backward
[rank0]:     loss.backward(**kwargs)
[rank0]:   File "/network/scratch/o/ortizgas/data/milabench/venv/torch/lib/python3.10/site-packages/torch/_tensor.py", line 521, in backward
[rank0]:     torch.autograd.backward(
[rank0]:   File "/network/scratch/o/ortizgas/data/milabench/venv/torch/lib/python3.10/site-packages/torch/autograd/__init__.py", line 289, in backward
[rank0]:     _engine_run_backward(
[rank0]:   File "/network/scratch/o/ortizgas/data/milabench/venv/torch/lib/python3.10/site-packages/torch/autograd/graph.py", line 768, in _engine_run_backward
[rank0]:     return Variable._execution_engine.run_backward(  # Calls into the C++ engine to run the backward pass
[rank0]: torch.OutOfMemoryError: CUDA out of memory. Tried to allocate 5.09 GiB. GPU 0 has a total capacity of 79.44 GiB of which 382.44 MiB is free. Including non-PyTorch memory, this process has 79.06 GiB memory in use. Of the allocated memory 74.67 GiB is allocated by PyTorch, and 1.02 GiB is reserved by PyTorch but unallocated. If reserved but unallocated memory is large try setting PYTORCH_CUDA_ALLOC_CONF=expandable_segments:True to avoid fragmentation.  See documentation for Memory Management  (https://pytorch.org/docs/stable/notes/cuda.html#environment-variables)
[rank1]: Traceback (most recent call last):
[rank1]:   File "/home/mila/o/ortizgas/CODE/milabench/benchmarks/rlhf/main.py", line 133, in <module>
[rank1]:     main()
[rank1]:   File "/home/mila/o/ortizgas/CODE/milabench/benchmarks/rlhf/main.py", line 124, in main
[rank1]:     trainer.train()
[rank1]:   File "/network/scratch/o/ortizgas/data/milabench/venv/torch/lib/python3.10/site-packages/trl/trainer/ppov2_trainer.py", line 465, in train
[rank1]:     accelerator.backward(loss)
[rank1]:   File "/network/scratch/o/ortizgas/data/milabench/venv/torch/lib/python3.10/site-packages/accelerate/accelerator.py", line 2196, in backward
[rank1]:     loss.backward(**kwargs)
[rank1]:   File "/network/scratch/o/ortizgas/data/milabench/venv/torch/lib/python3.10/site-packages/torch/_tensor.py", line 521, in backward
[rank1]:     torch.autograd.backward(
[rank1]:   File "/network/scratch/o/ortizgas/data/milabench/venv/torch/lib/python3.10/site-packages/torch/autograd/__init__.py", line 289, in backward
[rank1]:     _engine_run_backward(
[rank1]:   File "/network/scratch/o/ortizgas/data/milabench/venv/torch/lib/python3.10/site-packages/torch/autograd/graph.py", line 768, in _engine_run_backward
[rank1]:     return Variable._execution_engine.run_backward(  # Calls into the C++ engine to run the backward pass
[rank1]: torch.OutOfMemoryError: CUDA out of memory. Tried to allocate 5.09 GiB. GPU 1 has a total capacity of 79.44 GiB of which 1.40 GiB is free. Including non-PyTorch memory, this process has 78.03 GiB memory in use. Of the allocated memory 73.75 GiB is allocated by PyTorch, and 877.02 MiB is reserved by PyTorch but unallocated. If reserved but unallocated memory is large try setting PYTORCH_CUDA_ALLOC_CONF=expandable_segments:True to avoid fragmentation.  See documentation for Memory Management  (https://pytorch.org/docs/stable/notes/cuda.html#environment-variables)
[rank2]: Traceback (most recent call last):
[rank2]:   File "/home/mila/o/ortizgas/CODE/milabench/benchmarks/rlhf/main.py", line 133, in <module>
[rank2]:     main()
[rank2]:   File "/home/mila/o/ortizgas/CODE/milabench/benchmarks/rlhf/main.py", line 124, in main
[rank2]:     trainer.train()
[rank2]:   File "/network/scratch/o/ortizgas/data/milabench/venv/torch/lib/python3.10/site-packages/trl/trainer/ppov2_trainer.py", line 465, in train
[rank2]:     accelerator.backward(loss)
[rank2]:   File "/network/scratch/o/ortizgas/data/milabench/venv/torch/lib/python3.10/site-packages/accelerate/accelerator.py", line 2196, in backward
[rank2]:     loss.backward(**kwargs)
[rank2]:   File "/network/scratch/o/ortizgas/data/milabench/venv/torch/lib/python3.10/site-packages/torch/_tensor.py", line 521, in backward
[rank2]:     torch.autograd.backward(
[rank2]:   File "/network/scratch/o/ortizgas/data/milabench/venv/torch/lib/python3.10/site-packages/torch/autograd/__init__.py", line 289, in backward
[rank2]:     _engine_run_backward(
[rank2]:   File "/network/scratch/o/ortizgas/data/milabench/venv/torch/lib/python3.10/site-packages/torch/autograd/graph.py", line 768, in _engine_run_backward
[rank2]:     return Variable._execution_engine.run_backward(  # Calls into the C++ engine to run the backward pass
[rank2]: torch.OutOfMemoryError: CUDA out of memory. Tried to allocate 5.09 GiB. GPU 2 has a total capacity of 79.44 GiB of which 1.09 GiB is free. Including non-PyTorch memory, this process has 78.34 GiB memory in use. Of the allocated memory 74.11 GiB is allocated by PyTorch, and 830.31 MiB is reserved by PyTorch but unallocated. If reserved but unallocated memory is large try setting PYTORCH_CUDA_ALLOC_CONF=expandable_segments:True to avoid fragmentation.  See documentation for Memory Management  (https://pytorch.org/docs/stable/notes/cuda.html#environment-variables)
[rank3]: Traceback (most recent call last):
[rank3]:   File "/home/mila/o/ortizgas/CODE/milabench/benchmarks/rlhf/main.py", line 133, in <module>
[rank3]:     main()
[rank3]:   File "/home/mila/o/ortizgas/CODE/milabench/benchmarks/rlhf/main.py", line 124, in main
[rank3]:     trainer.train()
[rank3]:   File "/network/scratch/o/ortizgas/data/milabench/venv/torch/lib/python3.10/site-packages/trl/trainer/ppov2_trainer.py", line 465, in train
[rank3]:     accelerator.backward(loss)
[rank3]:   File "/network/scratch/o/ortizgas/data/milabench/venv/torch/lib/python3.10/site-packages/accelerate/accelerator.py", line 2196, in backward
[rank3]:     loss.backward(**kwargs)
[rank3]:   File "/network/scratch/o/ortizgas/data/milabench/venv/torch/lib/python3.10/site-packages/torch/_tensor.py", line 521, in backward
[rank3]:     torch.autograd.backward(
[rank3]:   File "/network/scratch/o/ortizgas/data/milabench/venv/torch/lib/python3.10/site-packages/torch/autograd/__init__.py", line 289, in backward
[rank3]:     _engine_run_backward(
[rank3]:   File "/network/scratch/o/ortizgas/data/milabench/venv/torch/lib/python3.10/site-packages/torch/autograd/graph.py", line 768, in _engine_run_backward
[rank3]:     return Variable._execution_engine.run_backward(  # Calls into the C++ engine to run the backward pass
[rank3]: torch.OutOfMemoryError: CUDA out of memory. Tried to allocate 5.09 GiB. GPU 3 has a total capacity of 79.44 GiB of which 1.33 GiB is free. Including non-PyTorch memory, this process has 78.10 GiB memory in use. Of the allocated memory 74.11 GiB is allocated by PyTorch, and 830.31 MiB is reserved by PyTorch but unallocated. If reserved but unallocated memory is large try setting PYTORCH_CUDA_ALLOC_CONF=expandable_segments:True to avoid fragmentation.  See documentation for Memory Management  (https://pytorch.org/docs/stable/notes/cuda.html#environment-variables)
  0%|          | 0/8 [00:13<?, ?it/s]
[rank0]:[W1212 15:59:37.707289462 ProcessGroupNCCL.cpp:1168] Warning: WARNING: process group has NOT been destroyed before we destruct ProcessGroupNCCL. On normal program exit, the application should call destroy_process_group to ensure that any pending NCCL operations have finished in this process. In rare cases this process can exit before this point and block the progress of another member of the process group. This constraint has always been present,  but this warning has only been added since PyTorch 2.4 (function operator())
W1212 15:59:38.728204 140021092886336 torch/distributed/elastic/multiprocessing/api.py:858] Sending process 1881157 closing signal SIGTERM
W1212 15:59:38.728551 140021092886336 torch/distributed/elastic/multiprocessing/api.py:858] Sending process 1881159 closing signal SIGTERM
W1212 15:59:38.728609 140021092886336 torch/distributed/elastic/multiprocessing/api.py:858] Sending process 1881160 closing signal SIGTERM
E1212 15:59:39.207154 140021092886336 torch/distributed/elastic/multiprocessing/api.py:833] failed (exitcode: 1) local_rank: 1 (pid: 1881158) of binary: /network/scratch/o/ortizgas/data/milabench/venv/torch/bin/python
Traceback (most recent call last):
  File "/network/scratch/o/ortizgas/data/milabench/venv/torch/bin/accelerate", line 8, in <module>
    sys.exit(main())
  File "/network/scratch/o/ortizgas/data/milabench/venv/torch/lib/python3.10/site-packages/accelerate/commands/accelerate_cli.py", line 48, in main
    args.func(args)
  File "/network/scratch/o/ortizgas/data/milabench/venv/torch/lib/python3.10/site-packages/accelerate/commands/launch.py", line 1165, in launch_command
    multi_gpu_launcher(args)
  File "/network/scratch/o/ortizgas/data/milabench/venv/torch/lib/python3.10/site-packages/accelerate/commands/launch.py", line 799, in multi_gpu_launcher
    distrib_run.run(args)
  File "/network/scratch/o/ortizgas/data/milabench/venv/torch/lib/python3.10/site-packages/torch/distributed/run.py", line 892, in run
    elastic_launch(
  File "/network/scratch/o/ortizgas/data/milabench/venv/torch/lib/python3.10/site-packages/torch/distributed/launcher/api.py", line 133, in __call__
    return launch_agent(self._config, self._entrypoint, list(args))
  File "/network/scratch/o/ortizgas/data/milabench/venv/torch/lib/python3.10/site-packages/torch/distributed/launcher/api.py", line 264, in launch_agent
    raise ChildFailedError(
torch.distributed.elastic.multiprocessing.errors.ChildFailedError: 
============================================================
/home/mila/o/ortizgas/CODE/milabench/benchmarks/rlhf/main.py FAILED
------------------------------------------------------------
Failures:
  <NO_OTHER_FAILURES>
------------------------------------------------------------
Root Cause (first observed failure):
[0]:
  time      : 2024-12-12_15:59:38
  host      : cn-n002.server.mila.quebec
  rank      : 1 (local_rank: 1)
  exitcode  : 1 (pid: 1881158)
  error_file: <N/A>
  traceback : To enable traceback see: https://pytorch.org/docs/stable/elastic/errors.html
============================================================
